# Test Button - Final Status and Summary

**Date:** January 2025  
**Status:** Working on Entity ID Mapping Issue

---

## Current Issue

The Test button creates YAML with invalid entity IDs like `"office"` instead of `"light.office"`. This causes HA to reject the automation with error:

```
not a valid value for dictionary value @ data['actions'][0]['repeat']['sequence'][0]['target']['entity_id']
```

---

## Root Cause Analysis

### What We Fixed:
1. ✅ Extract entity names from `devices_involved` instead of `query.extracted_entities`
2. ✅ Map devices to entity_ids using `EntityValidator.map_query_to_entities()`
3. ✅ Build `validated_entities` dict with proper mappings
4. ✅ Pass `validated_entities` to the suggestion

### What's Still Broken:
- The YAML generator receives `validated_entities={}` (empty dict)
- Despite proper mapping in logs: `'Office Light 1' → light.office`
- The validated_entities_text is generated but YAML still uses incorrect IDs

---

## Code Path

```python
# In test_suggestion_from_query (line 945-975):

1. Extract devices_involved: ["Office Light 1", "Office Light 2"] ✅
2. Call map_query_to_entities() → Returns: {'Office Light 1': 'light.office', ...} ✅
3. Build entity_mapping: Validate ✅
4. Add to test_suggestion: test_suggestion['validated_entities'] = entity_mapping ✅
5. Call generate_automation_yaml(test_suggestion, ...) 
   → But logs show: "Added validated_entities: {}" ❌

# In generate_automation_yaml (line 251-260):

1. Check: 'validated_entities' in suggestion and suggestion['validated_entities'] 
   → Returns False because dict is empty
2. Fall through to: validated_entities_text = "CRITICAL: No validated entities found..." ❌
```

---

## The Actual Problem

Looking at the logs more carefully:

```
🔍 devices_involved from suggestion: ['Office Light 1', 'Office Light 2']
🔍 Mapping devices to entity_ids...
🔍 resolved_entities result: {}  ← EMPTY!
⚠️ Device 'Office Light 1' not found in resolved_entities
⚠️ Device 'Office Light 2' not found in resolved_entities
🔍 Added validated_entities: {}  ← EMPTY!
```

The `map_query_to_entities()` call is returning an empty dict **before** we check `resolved_entities`.

Then later in the logs, it's called AGAIN (by generate_automation_yaml) and it works:
```
✅ Mapped 'Office Light 1' to light.office
✅ Mapped 'Office Light 2' to light.office
```

---

## The Fix

The problem is that `EntityValidator` is being instantiated without proper data API client. Check logs:

```
Data API client not available, using empty entity list
```

So on the FIRST call (in test endpoint), it has no entities to search.
On the SECOND call (in generate_automation_yaml), it has access to entities.

We need to ensure the first call has access to entity data.

---

## Next Steps

1. Check why Data API client is not available in test endpoint
2. Ensure EntityValidator has proper initialization
3. Pass entity data from query.extracted_entities to the validator
4. Verify that validate_entities dict is properly populated before passing to generate_automation_yaml

